<?xml version="1.0"?>
<robot name="esdlbot_demo_base">

  <material name="black">
    <color rgba="0 0 0 1"/>
  </material>
  <material name="gray">
    <color rgba="0.72 0.72 0.72 1"/>
  </material>
  <material name="white">
    <color rgba="1 1 1 1"/>
  </material>
  
  <link name="base_footprint"/>
  
  <joint name="model_joint" type="fixed">
    <parent link="base_footprint" />
    <child link = "base_link" />
    <origin xyz="0.0 0.0 0.0735" rpy="0.0 0.0 0.0" />
  </joint>
  
  <link name="base_link">
    <!-- Main body -->
    <visual>
      <geometry>
        <box size="0.185 0.03 0.03"/>
      </geometry>
      <origin xyz="-0.1075 0.0 0.0" rpy="0.0 0.0 0.0"/>
      <material name="gray"/>
    </visual>
    
    <!-- Fore body -->
    <visual>
      <geometry>
        <box size="0.03 0.20 0.03"/>
      </geometry>
      <origin xyz="0.0 0.0 0.0" rpy="0.0 0.0 0.0"/>

    </visual>
        
    <!-- Rear body -->
    <visual>
      <geometry>
        <box size="0.03 0.20 0.03"/>
      </geometry>
      <origin xyz="-0.215 0.0 0.0" rpy="0.0 0.0 0.0"/>

    </visual>
    
    <!-- Left Motor -->
    <visual>
      <geometry>
        <box size="0.042 0.042 0.042"/>
      </geometry>
      <origin xyz="0.0 0.079 -0.036" rpy="0.0 0.0 0.0"/>
    </visual>
    
    <!-- Right Motor -->
    <visual>
      <geometry>
        <box size="0.042 0.042 0.042"/>
      </geometry>
      <origin xyz="0.0 -0.079 -0.036" rpy="0.0 0.0 0.0"/>
    </visual>
    
    <!-- Left back wheel base -->
    <visual>
      <geometry>
        <box size="0.034 0.040 0.024"/>
      </geometry>
      <origin xyz="-0.215 0.08 -0.027" rpy="0.0 0.0 0.0"/>
    </visual>
    
    <!-- Right back wheel base -->
    <visual>
      <geometry>
        <box size="0.034 0.040 0.024"/>
      </geometry>
      <origin xyz="-0.215 -0.08 -0.027" rpy="0.0 0.0 0.0"/>
    </visual>
    
    <!-- Left back wheel -->
    <visual>
      <geometry>
        <cylinder length="0.013" radius="0.0125"/>
      </geometry>
      <origin xyz="-0.215 -0.08 -0.061" rpy="1.5708 0.0 0.0"/>
      <material name="white"/>
    </visual>
    
    <!-- Right back wheel -->
    <visual>
      <geometry>
        <cylinder length="0.013" radius="0.0125"/>
      </geometry>
      <origin xyz="-0.215 0.08 -0.061" rpy="1.5708 0.0 0.0"/>
    </visual>

  </link>
   
  <joint name="Left_wheel_joint" type="continuous">
    <parent link="base_link" />
    <child link = "left_wheel" />
    <origin xyz="0.0 0.123 -0.04" rpy="0.0 0.0 0.0" />
    <axis xyz="0 1 0"/>
  </joint>
  
  <link name="left_wheel">
    <visual>
      <geometry>
        <cylinder length="0.025" radius="0.0335"/>
      </geometry>
      <origin xyz="0.0 0.0 0.0" rpy="1.5708 0.0 0.0"/>
      <material name="black"/>
    </visual>
  </link>
  
  <joint name="Right_wheel_joint" type="continuous">
    <parent link="base_link" />
    <child link = "Right_wheel" />
    <origin xyz="0.0 -0.123 -0.04" rpy="0.0 0.0 0.0" />
    <axis xyz="0 1 0"/>
  </joint>
  
  <link name="Right_wheel">
    <visual>
      <geometry>
        <cylinder length="0.025" radius="0.0335"/>
      </geometry>
      <origin xyz="0.0 0.0 0.0" rpy="1.5708 0.0 0.0"/>
      <material name="black"/>
    </visual>
  </link>
  
  <joint name="Imu_joint" type="fixed">
    <parent link="base_link" />
    <child link = "imu_frame" />
    <origin xyz="-0.075 0.0 0.03" rpy="0.0 0.0 0.0" />
  </joint>
  
  <link name="imu_frame" />
  

  
  
    

</robot>
