<?xml version="1.0"?>
<robot name="esdlbot_V1_base">

  <material name="black">
    <color rgba="0 0 0 1"/>
  </material>
  <material name="gray">
    <color rgba="0.72 0.72 0.72 1"/>
  </material>
  <material name="white">
    <color rgba="1 1 1 1"/>
  </material>
  
  <link name="base_footprint"/>
  
  <joint name="model_joint" type="fixed">
    <parent link="base_footprint" />
    <child link = "base_link" />
    <origin xyz="0.0 0.0 0.144" rpy="0.0 0.0 0.0" />
  </joint>
  
  <link name="base_link">
    <!-- Main body -->
    <visual>
      <geometry>
        <box size="0.03 0.353 0.06"/>
      </geometry>
      <origin xyz="-0.225 0.0 0.015" rpy="0.0 0.0 0.0"/>
      <material name="gray"/>
    </visual>
    
    <!-- right body -->
    <visual>
      <geometry>
        <box size="0.3 0.03 0.03"/>
      </geometry>
      <origin xyz="-0.06 -0.1615 0.0" rpy="0.0 0.0 0.0"/>
    </visual>
        
    <!-- left body -->
    <visual>
      <geometry>
        <box size="0.3 0.03 0.03"/>
      </geometry>
      <origin xyz="-0.06 0.1615 0.0" rpy="0.0 0.0 0.0"/>
    </visual>
    
    <!-- middle body -->
    <visual>
      <geometry>
        <box size="0.31 0.03 0.03"/>
      </geometry>
      <origin xyz="-0.055 0.0 0.0" rpy="0.0 0.0 0.0"/>
    </visual>
    
    <!-- Left back wheel base -->
    <visual>
      <geometry>
        <box size="0.06 0.07 0.04"/>
      </geometry>
      <origin xyz="-0.225 0.08 -0.035" rpy="0.0 0.0 0.0"/>
    </visual>
    
    <!-- Right back wheel base -->
    <visual>
      <geometry>
        <box size="0.06 0.07 0.04"/>
      </geometry>
      <origin xyz="-0.225 -0.08 -0.035" rpy="0.0 0.0 0.0"/>
    </visual>
    
    <!-- Left back wheel -->
    <visual>
      <geometry>
        <cylinder length="0.025" radius="0.04"/>
      </geometry>
      <origin xyz="-0.228 -0.08 -0.104" rpy="1.5708 0.0 0.0"/>
      <material name="white"/>
    </visual>
    
    <!-- Right back wheel -->
    <visual>
      <geometry>
        <cylinder length="0.025" radius="0.04"/>
      </geometry>
      <origin xyz="-0.228 0.08 -0.104" rpy="1.5708 0.0 0.0"/>
    </visual>
    
    <!-- Raise column-->
    <visual>
      <geometry>
        <box size="0.03 0.03 1.65"/>
      </geometry>
      <origin xyz="-0.195 0.0 0.84" rpy="0.0 0.0 0.0"/>
    </visual>
    
    <!-- 2F Main body -->
    <visual>
      <geometry>
        <box size="0.03 0.353 0.03"/>
      </geometry>
      <origin xyz="-0.225 0.0 0.11" rpy="0.0 0.0 0.0"/>
      <material name="gray"/>
    </visual>
    
    <!-- 2F right body -->
    <visual>
      <geometry>
        <box size="0.16 0.03 0.03"/>
      </geometry>
      <origin xyz="-0.13 -0.125 0.11" rpy="0.0 0.0 0.0"/>
    </visual>
        
    <!-- 2F left body -->
    <visual>
      <geometry>
        <box size="0.16 0.03 0.03"/>
      </geometry>
      <origin xyz="-0.13 0.125 0.11" rpy="0.0 0.0 0.0"/>
    </visual>

  </link>
   
  <joint name="Left_wheel_joint" type="continuous">
    <parent link="base_link" />
    <child link = "left_wheel" />
    <origin xyz="0.0 0.0765 -0.03" rpy="0.0 0.0 0.0" />
    <axis xyz="0 1 0"/>
  </joint>
  
  <link name="left_wheel">
    <visual>
      <geometry>
        <cylinder length="0.045" radius="0.114"/>
      </geometry>
      <origin xyz="0.0 0.0 0.0" rpy="1.5708 0.0 0.0"/>
      <material name="black"/>
    </visual>
  </link>
  
  <joint name="Right_wheel_joint" type="continuous">
    <parent link="base_link" />
    <child link = "Right_wheel" />
    <origin xyz="0.0 -0.0765 -0.03" rpy="0.0 0.0 0.0" />
    <axis xyz="0 1 0"/>
  </joint>
  
  <link name="Right_wheel">
    <visual>
      <geometry>
        <cylinder length="0.045" radius="0.114"/>
      </geometry>
      <origin xyz="0.0 0.0 0.0" rpy="1.5708 0.0 0.0"/>
      <material name="black"/>
    </visual>
  </link>
  
  <joint name="Imu_joint" type="fixed">
    <parent link="base_link" />
    <child link = "imu_frame" />
    <origin xyz="-0.225 0.045 0.06" rpy="0.0 0.0 0.0" />
  </joint>
  
  <link name="imu_frame" />
  

  
  
    

</robot>
